<?xml version="1.0"?>

<robot name="ranger_mini_xray_source" 
    xmlns:xacro="http://ros.org/wiki/xacro">

    <!-- Material definitions -->
    <material name="black">
        <color rgba="0.1 0.1 0.1 1" />
    </material>
    <material name="white">
        <color rgba="1 1 1 1" />
    </material>
    <material name="dark_grey">
        <color rgba="0.3 0.3 0.3 1" />
    </material>
    <material name="metallic_grey">
        <color rgba="0.7 0.7 0.7 1" />
    </material>
    <material name="source_red">
        <color rgba="0.8 0.2 0.2 1" />
    </material>

    <!-- Base link -->
    <link name="base_link">
        <inertial>
            <origin xyz="0.0 0.0 0.0"/>
            <mass value="15"/>
            <inertia ixx="0.5" ixy="0.0" ixz="0.0" iyy="0.5" iyz="0.0" izz="0.5"/>
        </inertial>
        <visual>
            <origin xyz="0 0 0" rpy="1.57 0 3.14 " />
            <geometry>
                <mesh filename="package://ranger_mini_v2/meshes/ranger_base.dae" />
            </geometry>
            <material name="metallic_grey" />
        </visual>
        <collision>
            <origin xyz="0 0 -0.1" rpy="0 0 0" />
            <geometry>
                <box size="0.5 0.35 0.2"/>
            </geometry>
        </collision>
 
    </link>

   <link name="fl_steering_wheel_link">
        <inertial>
            <origin xyz="0.0 0.0 0.0"/>
            <mass value="1"/>
            <inertia ixx="0.01" ixy="0.0" ixz="0.0" iyy="0.01" iyz="0.0" izz="0.01"/>
        </inertial>
        <visual>
            <origin xyz="-0.23 -0.194 0.1" rpy="-3.14 0 3.14 " />
            <geometry>
                    <mesh filename="package://ranger_mini_v2/meshes/fl.stl" />
            </geometry>
            <material name="dark_grey" />
        </visual>
        <collision>
            <origin xyz="0 0 0.008" rpy="0 0 0" />
            <geometry>
                <cylinder radius="0.001" length="0.001"/>
            </geometry>
        </collision>
        <collision>
            <origin xyz="0 0 0" rpy="0 0 0" />
            <geometry>
                <cylinder radius="0.001" length="0.001"/>
            </geometry>
        </collision>
    </link>
    <joint name="fl_steering_wheel" type="revolute">
        <origin xyz="0.23 0.206 -0.1" rpy="0 0 0" />
        <parent link="base_link"/>
        <child link="fl_steering_wheel_link"/>
        <axis xyz="0 0 1" rpy="0 0 0" />
        <limit effort="5" velocity="6.28"  lower="-2.1" upper="2.1" />
    </joint>

        <link name="fl_wheel_link">
            <inertial>
                <mass value="8" />
                <origin xyz="0 0 0" />
                <inertia ixx="0.1171" ixy="0" ixz="0" iyy="0.1361" iyz="0" izz="0.1171" />
            </inertial>
            <visual>
                <origin xyz="0 0 0" rpy="1.57 0 0" />
                <geometry>
                    <cylinder length="0.01" radius="0.01" />
                </geometry>
                <material name="black" />
            </visual>
            <collision>
                <origin xyz="0 0 0" rpy="1.57 0 0" />
                <geometry>
                    <cylinder length="0.08" radius="0.08" />
                </geometry>
                     <contact>
                         <ode>
                        <min_depth>0.001</min_depth>
                         </ode>
                    </contact>
            </collision>
        </link>

        <joint name="fl_wheel" type="continuous">
            <origin xyz="0.03 0.01 -0.12" rpy="0 0 0" />
            <parent link="fl_steering_wheel_link"/>
            <child link="fl_wheel_link"/>
            <axis xyz="0 1 0" rpy="0 0 0" />
        </joint>


   <link name="fr_steering_wheel_link">
        <inertial>
            <origin xyz="0.0 0.0 0.0" rpy="0.0 0.0 0.0"/>
            <mass value="1"/>
            <inertia ixx="0.01" ixy="0.0" ixz="0.0" iyy="0.01" iyz="0.0" izz="0.01"/>
        </inertial>
        <visual>
            <origin xyz="-0.23 0.194 0.1" rpy="-3.14 0 3.14 " />
            <geometry>
                <mesh filename="package://ranger_mini_v2/meshes/fr.stl" />
            </geometry>
            <material name="dark_grey" />
        </visual>
        <collision>
            <origin xyz="0 0 0.008" rpy="0 0 0" />
            <geometry>
                <cylinder radius="0.001" length="0.001"/>
            </geometry>
        </collision>
    </link>
    <joint name="fr_steering_wheel" type="revolute">
        <origin xyz="0.23 -0.206 -0.1" rpy="0 0 0" />
        <parent link="base_link"/>
        <child link="fr_steering_wheel_link"/>
        <axis xyz="0 0 1" rpy="0 0 0" />
        <limit effort="5" velocity="6.28"  lower="-2.1" upper="2.1" />
    </joint>

        <link name="fr_wheel_link">
            <inertial>
                <mass value="8" />
                <origin xyz="0 0 0" />
                <inertia ixx="0.1171" ixy="0" ixz="0" iyy="0.1361" iyz="0" izz="0.1171" />
            </inertial>
            <visual>
                <origin xyz="0 0 0" rpy="1.57 0 0" />
                <geometry>
                    <cylinder length="0.01" radius="0.01" />
                </geometry>
                <material name="black" />
            </visual>
            <collision>
                <origin xyz="0 0 0" rpy="1.57 0 0" />
                <geometry>
                    <cylinder length="0.08" radius="0.085" />
                </geometry>
                     <contact>
                         <ode>
                        <min_depth>0.001</min_depth>
                         </ode>
                    </contact>
            </collision>
        </link>

        <joint name="fr_wheel" type="continuous">
            <origin xyz="0.0 0.0 -0.12" rpy="0 0 0" />
            <parent link="fr_steering_wheel_link"/>
            <child link="fr_wheel_link"/>
            <axis xyz="0 1 0" rpy="0 0 0" />
        </joint>


   <link name="rl_steering_wheel_link">
        <inertial>
            <origin xyz="0.0 0.0 0.0" rpy="0.0 0.0 0.0"/>
            <mass value="1"/>
            <inertia ixx="0.01" ixy="0.0" ixz="0.0" iyy="0.01" iyz="0.0" izz="0.01"/>
        </inertial>
        <visual>
            <origin xyz="-0.23 -0.194 0.1" rpy="-3.14 0 3.14 " />
            <geometry>
                    <mesh filename="package://ranger_mini_v2/meshes/fl.stl" />
            </geometry>
            <material name="dark_grey" />
        </visual>
        <collision>
            <origin xyz="0 0 0.008" rpy="0 0 0" />
            <geometry>
                <cylinder radius="0.001" length="0.001"/>
            </geometry>
        </collision>
    </link>
    <joint name="rl_steering_wheel" type="revolute">
        <origin xyz="-0.23 0.206 -0.1" rpy="0 0 0" />
        <parent link="base_link"/>
        <child link="rl_steering_wheel_link"/>
        <axis xyz="0 0 1" rpy="0 0 0" />
        <limit effort="5" velocity="6.28"  lower="-2.1" upper="2.1" />
    </joint>

        <link name="rl_wheel_link">
            <inertial>
                <mass value="8" />
                <origin xyz="0 0 0" />
                <inertia ixx="0.1171" ixy="0" ixz="0" iyy="0.1361" iyz="0" izz="0.1171" />
            </inertial>
            <visual>
                <origin xyz="0 0 0" rpy="1.57 0 0" />
                <geometry>
                    <cylinder length="0.01" radius="0.01" />
                </geometry>
                <material name="black" />
            </visual>
            <collision>
                <origin xyz="0 0 0" rpy="1.57 0 0" />
                <geometry>
                    <cylinder length="0.08" radius="0.08" />
                </geometry>
                     <contact>
                         <ode>
                        <min_depth>0.001</min_depth>
                         </ode>
                    </contact>
            </collision>
        </link>

        <joint name="rl_wheel" type="continuous">
            <origin xyz="0.0 0.0 -0.12 " rpy="0 0 0" />
            <parent link="rl_steering_wheel_link"/>
            <child link="rl_wheel_link"/>
            <axis xyz="0 1 0" rpy="0 0 0" />
        </joint>


   <link name="rr_steering_wheel_link">
        <inertial>
            <origin xyz="0.0 0.0 0.0"/>
            <mass value="1"/>
            <inertia ixx="0.01" ixy="0.0" ixz="0.0" iyy="0.01" iyz="0.0" izz="0.01"/>
        </inertial>
        <visual>
            <origin xyz="-0.23 0.194 0.1" rpy="-3.14 0 3.14 " />
            <geometry>
                    <mesh filename="package://ranger_mini_v2/meshes/fr.stl" />
            </geometry>
            <material name="dark_grey" />
        </visual>
        <collision>
            <origin xyz="0 0 0" rpy="0 0 0" />
            <geometry>
                <cylinder radius="0.001" length="0.001"/>
            </geometry>
        </collision>
    </link>
    <joint name="rr_steering_wheel" type="revolute">
        <origin xyz="-0.23 -0.206 -0.1" rpy="0 0 0" />
        <parent link="base_link"/>
        <child link="rr_steering_wheel_link"/>
        <axis xyz="0 0 1" rpy="0 0 0" />
        <limit effort="5" velocity="6.28"  lower="-2.1" upper="2.1" />
    </joint>

        <link name="rr_wheel_link">
            <inertial>
                <mass value="8" />
                <origin xyz="0 0 0" />
                <inertia ixx="0.1171" ixy="0" ixz="0" iyy="0.1361" iyz="0" izz="0.1171" />
            </inertial>
            <visual>
                <origin xyz="0.0 0.0 0.0" rpy="1.57 0 0" />
                <geometry>
                    <cylinder length="0.01" radius="0.01" />
                </geometry>
                <material name="black" />
            </visual>
            <collision>
                <origin xyz="0 0 0" rpy="1.57 0 0" />
                <geometry>
                    <cylinder length="0.08" radius="0.08" />
                </geometry>
                     <contact>
                         <ode>
                        <min_depth>0.001</min_depth>
                         </ode>
                    </contact>
            </collision>
        </link>

        <joint name="rr_wheel" type="continuous">
            <origin xyz="0.0 0.0 -0.12 " rpy="0 0 0" />
            <parent link="rr_steering_wheel_link"/>
            <child link="rr_wheel_link"/>
            <axis xyz="0 1 0" rpy="0 0 0" />
        </joint>

    <!-- X-ray Source Support Cylinder - Mimics the scanner -->
    <link name="source_support_cylinder">
        <inertial>
            <origin xyz="0.0 0.0 0.6"/>
            <mass value="8"/>
            <inertia ixx="0.2" ixy="0.0" ixz="0.0" iyy="0.2" iyz="0.0" izz="0.2"/>
        </inertial>
        <visual>
            <origin xyz="0 0 0.2" rpy="0 0 0" />
            <geometry>
                <cylinder radius="0.08" length="1.4"/>
            </geometry>
            <material name="source_red" />
        </visual>
        <collision>
            <origin xyz="0 0 0.2" rpy="0 0 0" />
            <geometry>
                <cylinder radius="0.08" length="1.4"/>
            </geometry>
        </collision>
    </link>

    <joint name="source_support_cylinder_joint" type="fixed">
        <origin xyz="-0.16 0 0.2" rpy="0 0 0" />
        <parent link="base_link"/>
        <child link="source_support_cylinder"/>
    </joint>

	<transmission name="fl_steering_wheel_trans">
      <type>transmission_interface/SimpleTransmission</type>
      <joint name="fl_steering_wheel">
		<hardwareInterface>hardware_interface/PositionJointInterface</hardwareInterface>
      </joint>
	  <actuator name="fl_steering_wheel_motor">
		<hardwareInterface>hardware_interface/PositionJointInterface</hardwareInterface>
		<mechanicalReduction>30</mechanicalReduction>
      </actuator>
	</transmission>

	<transmission name="fr_steering_wheel_trans">
      <type>transmission_interface/SimpleTransmission</type>
      <joint name="fr_steering_wheel">
		<hardwareInterface>hardware_interface/PositionJointInterface</hardwareInterface>
      </joint>
	  <actuator name="fr_steering_wheel_motor">
		<hardwareInterface>hardware_interface/PositionJointInterface</hardwareInterface>
		<mechanicalReduction>30</mechanicalReduction>
      </actuator>
	</transmission>

	<transmission name="rl_steering_wheel_trans">
      <type>transmission_interface/SimpleTransmission</type>
      <joint name="rl_steering_wheel">
		<hardwareInterface>hardware_interface/PositionJointInterface</hardwareInterface>
      </joint>
	  <actuator name="rl_steering_wheel_motor">
		<hardwareInterface>hardware_interface/PositionJointInterface</hardwareInterface>
		<mechanicalReduction>30</mechanicalReduction>
      </actuator>
	</transmission>

	<transmission name="rr_steering_wheel_trans">
      <type>transmission_interface/SimpleTransmission</type>
      <joint name="rr_steering_wheel">
		<hardwareInterface>hardware_interface/PositionJointInterface</hardwareInterface>
      </joint>
	  <actuator name="rr_steering_wheel_motor">
		<hardwareInterface>hardware_interface/PositionJointInterface</hardwareInterface>
		<mechanicalReduction>30</mechanicalReduction>
      </actuator>
	</transmission>

	<transmission name="fl_wheel_trans">
      <type>transmission_interface/SimpleTransmission</type>
      <joint name="fl_wheel">
		<hardwareInterface>hardware_interface/VelocityJointInterface</hardwareInterface>
      </joint>
	  <actuator name="fl_wheel_motor">
		<hardwareInterface>hardware_interface/VelocityJointInterface</hardwareInterface>
		<mechanicalReduction>30</mechanicalReduction>
      </actuator>
	</transmission>

	<transmission name="fr_wheel_trans">
      <type>transmission_interface/SimpleTransmission</type>
      <joint name="fr_wheel">
		<hardwareInterface>hardware_interface/VelocityJointInterface</hardwareInterface>
      </joint>
	  <actuator name="fr_wheel_motor">
		<hardwareInterface>hardware_interface/VelocityJointInterface</hardwareInterface>
		<mechanicalReduction>30</mechanicalReduction>
      </actuator>
	</transmission>

	<transmission name="rl_wheel_trans">
      <type>transmission_interface/SimpleTransmission</type>
      <joint name="rl_wheel">
		<hardwareInterface>hardware_interface/VelocityJointInterface</hardwareInterface>
      </joint>
	  <actuator name="rl_wheel_motor">
		<hardwareInterface>hardware_interface/VelocityJointInterface</hardwareInterface>
		<mechanicalReduction>30</mechanicalReduction>
      </actuator>
	</transmission>

	<transmission name="rr_wheel_trans">
      <type>transmission_interface/SimpleTransmission</type>
      <joint name="rr_wheel">
		<hardwareInterface>hardware_interface/VelocityJointInterface</hardwareInterface>
      </joint>
	  <actuator name="rr_wheel_motor">
		<hardwareInterface>hardware_interface/VelocityJointInterface</hardwareInterface>
		<mechanicalReduction>30</mechanicalReduction>
      </actuator>
	</transmission>
  <!-- Include accessories (3D LiDAR and camera) -->
  <xacro:include filename="$(find ranger_mini_v2_gazebo)/xacro/accessories_source.urdf.xacro" />

  <!-- Gazebo ROS Control Plugin -->
  <gazebo>
    <plugin name="gazebo_ros_control" filename="libgazebo_ros_control.so">
      <robotNamespace>/xray_source</robotNamespace>
              <robotParam>robot_description</robotParam>
      <robotSimType>gazebo_ros_control/DefaultRobotHWSim</robotSimType>
    </plugin>
  </gazebo>

</robot> 